<?xml version="1.0" ?>
<!-- =================================================================================== -->
<!-- |    This document was autogenerated by xacro from ./Combination.xacro            | -->
<!-- |    EDITING THIS FILE BY HAND IS NOT RECOMMENDED                                 | -->
<!-- =================================================================================== -->
<!--该文件是用于pnc识别使用 没有进行初始关节角度偏移-->
<robot name="robot">
  <!-- 定义颜色材料 -->
  <material name="body_material">
    <color rgba="0.17 0.17 0.17 1"/>
  </material>
  <material name="link_1_material">
    <color rgba="0.95 0.95 0.93 1"/>
  </material>
  <material name="link_2_material">
    <color rgba="0.82 0.84 0.85 1"/>
  </material>
  <material name="link_3_material">
    <color rgba="0.3 0.3 0.3 1"/>
  </material>
  <material name="link_4_material">
    <color rgba="0.05 0.05 0.05 1"/>
  </material>
  <!--身体部分body-->
  <link name="base_link">
    <!--惯性矩阵-->
    <inertial>
      <origin rpy="0 0 0" xyz="0.00015 0.00075 -0.004"/>
      <mass value="5.0"/>
      <inertia ixx="0.04181" ixy="-1e-05" ixz="5e-05" iyy="0.0558" iyz="2e-05" izz="0.0793"/>
    </inertial>
    <!--可视化-->
    <visual>
      <origin rpy="0 0 0" xyz="0 0 0"/>
      <geometry>
        <mesh filename="package://robot_description/robot/meshes/base_link.STL"/>
      </geometry>
      <material name="body_material"/>
    </visual>
    <!--碰撞-->
    <collision>
      <origin rpy="0 0 0" xyz="0 0 0"/>
      <geometry>
        <box size="0.256 0.256 0.118"/>
      </geometry>
    </collision>
  </link>
  <!--joint1-->
  <joint name="leg1_joint1" type="revolute">
    <!--两个坐标系（link）的相对偏移-->
    <origin rpy="-0.0 0 0" xyz="0.177 -0.0755 0.0"/>
    <parent link="base_link"/>
    <child link="leg1_link1"/>
    <axis xyz="1 0 0"/>
    <dynamics damping="0.01" friction="0.2"/>
    <limit effort="36.0" lower="-3.14" upper="3.14" velocity="17.3"/>
  </joint>
  <!--link1-->
  <link name="leg1_link1">
    <!--质心偏移-->
    <inertial>
      <origin rpy="0 0 0" xyz="-0.00461 0.02471 0.00019"/>
      <mass value="0.68678"/>
      <inertia ixx="0.00051" ixy="5e-05" ixz="0.0" iyy="0.0005" iyz="-0.0" izz="0.00057"/>
    </inertial>
    <visual>
      <origin rpy="0 0 0" xyz="0 0 0"/>
      <geometry>
        <mesh filename="package://robot_description/robot/meshes/leg1_link1.STL"/>
      </geometry>
      <material name="link_1_material"/>
    </visual>
    <collision>
      <origin rpy="1.57 0 0" xyz="0 0.033 0"/>
      <geometry>
        <cylinder length="0.06" radius="0.038"/>
      </geometry>
    </collision>
  </link>
  <!--joint2-->
  <joint name="leg1_joint2" type="revolute">
    <!--两个坐标系（link）的相对偏移-->
    <origin rpy="0 0 0" xyz="0.0 -0.0993 0.0"/>
    <parent link="leg1_link1"/>
    <child link="leg1_link2"/>
    <axis xyz="0 1 0"/>
    <dynamics damping="0.01" friction="0.2"/>
    <limit effort="36.0" lower="-3.14" upper="3.14" velocity="17.3"/>
  </joint>
  <!--link2-->
  <link name="leg1_link2">
    <!--质心偏移-->
    <inertial>
      <origin rpy="0 0 0" xyz="-0.00238 0.02441 -0.04244"/>
      <mass value="1.22859"/>
      <inertia ixx="0.00754" ixy="8e-05" ixz="0.00033" iyy="0.00682" iyz="0.00128" izz="0.00167"/>
    </inertial>
    <visual>
      <origin rpy="0 0 0" xyz="0 0 0"/>
      <geometry>
        <mesh filename="package://robot_description/robot/meshes/leg1_link2.STL"/>
      </geometry>
      <material name="link_2_material"/>
    </visual>
    <!--圆柱和盒子组合-->
    <collision>
      <origin rpy="1.57 0 0" xyz="0 0.036 0"/>
      <geometry>
        <cylinder length="0.117" radius="0.038"/>
      </geometry>
    </collision>
    <collision>
      <origin rpy="0 1.57 0" xyz="0 0 -0.125"/>
      <geometry>
        <box size="0.165 0.04 0.06"/>
      </geometry>
    </collision>
  </link>
  <!--joint3-->
  <joint name="leg1_joint3" type="revolute">
    <!--两个坐标系（link）的相对偏移-->
    <origin rpy="0 0 0" xyz="0.0 -0.0 -0.21"/>
    <parent link="leg1_link2"/>
    <child link="leg1_link3"/>
    <axis xyz="0 1 0"/>
    <dynamics damping="0.01" friction="0.2"/>
    <limit effort="36.0" lower="-3.14" upper="3.14" velocity="17.3"/>
  </joint>
  <!--link3-->
  <link name="leg1_link3">
    <!--质心偏移-->
    <inertial>
      <origin rpy="0 0 0" xyz="0.00418 -0.0 -0.09392"/>
      <mass value="0.20045"/>
      <inertia ixx="0.00094" ixy="-0.0" ixz="-3e-05" iyy="0.00094" iyz="-0.0" izz="3e-05"/>
    </inertial>
    <visual>
      <origin rpy="0 0 0" xyz="0 0 0"/>
      <geometry>
        <mesh filename="package://robot_description/robot/meshes/leg1_link3.STL"/>
      </geometry>
      <material name="link_3_material"/>
    </visual>
    <collision>
      <origin rpy="0 0 0" xyz="0 0 -0.105"/>
      <geometry>
        <cylinder length="0.21" radius="0.019"/>
      </geometry>
    </collision>
  </link>
  <!--joint4-->
  <joint name="leg1_joint4" type="fixed">
    <!--两个坐标系（link）的相对偏移-->
    <origin rpy="0 0 0" xyz="0.0 -0.0 -0.21"/>
    <parent link="leg1_link3"/>
    <child link="leg1_link4"/>
    <axis xyz="0 0 0"/>
    <!-- <dynamics damping="0 friction="0"/>
        <limit effort="0" velocity="0" lower="0" upper="0" /> -->
  </joint>
  <!--link4-->
  <link name="leg1_link4">
    <!--质心偏移-->
    <inertial>
      <origin rpy="0 0 0" xyz="-0.00432 -0.0 -0.00515"/>
      <mass value="0.01658"/>
      <inertia ixx="1e-05" ixy="-0.0" ixz="0.0" iyy="1e-05" iyz="-0.0" izz="1e-05"/>
    </inertial>
    <visual>
      <origin rpy="0 0 0" xyz="0 0 0"/>
      <geometry>
        <mesh filename="package://robot_description/robot/meshes/leg1_link4.STL"/>
      </geometry>
      <material name="link_4_material"/>
    </visual>
    <collision>
      <origin rpy="0 0 0" xyz="0 0 0"/>
      <geometry>
        <sphere radius="0.018"/>
      </geometry>
    </collision>
  </link>
  <!-- 指定执行机构 -->
  <!--motor1-->
  <transmission name="leg1_joint1_tran">
    <!--指定传动类型-->
    <type>transmission_interface/SimpleTransmission</type>
    <!--传动系统所连接的关节-->
    <joint name="leg1_joint1">
      <!--硬件接口-->
      <hardwareInterface>hardware_interface/EffortJointInterface</hardwareInterface>
    </joint>
    <!--执行器名称-->
    <actuator name="leg1_joint1_motor">
      <hardwareInterface>hardware_interface/EffortJointInterface</hardwareInterface>
      <!--减速比-->
      <mechanicalReduction>1</mechanicalReduction>
    </actuator>
  </transmission>
  <!--motor2-->
  <transmission name="leg1_joint2_tran">
    <type>transmission_interface/SimpleTransmission</type>
    <joint name="leg1_joint2">
      <hardwareInterface>hardware_interface/EffortJointInterface</hardwareInterface>
    </joint>
    <actuator name="leg1_joint2_motor">
      <hardwareInterface>hardware_interface/EffortJointInterface</hardwareInterface>
      <mechanicalReduction>1</mechanicalReduction>
    </actuator>
  </transmission>
  <!--motor3-->
  <transmission name="leg1_joint3_tran">
    <type>transmission_interface/SimpleTransmission</type>
    <joint name="leg1_joint3">
      <hardwareInterface>hardware_interface/EffortJointInterface</hardwareInterface>
    </joint>
    <actuator name="leg1_joint3_motor">
      <hardwareInterface>hardware_interface/EffortJointInterface</hardwareInterface>
      <mechanicalReduction>1</mechanicalReduction>
    </actuator>
  </transmission>
  <!--joint1-->
  <joint name="leg2_joint1" type="revolute">
    <!--两个坐标系（link）的相对偏移-->
    <origin rpy="0.0 0 0" xyz="0.177 0.0755 0.0"/>
    <parent link="base_link"/>
    <child link="leg2_link1"/>
    <axis xyz="1 0 0"/>
    <dynamics damping="0.01" friction="0.2"/>
    <limit effort="36.0" lower="-3.14" upper="3.14" velocity="17.3"/>
  </joint>
  <!--link1-->
  <link name="leg2_link1">
    <!--质心偏移-->
    <inertial>
      <origin rpy="0 0 0" xyz="-0.00461 -0.02471 0.00019"/>
      <mass value="0.68678"/>
      <inertia ixx="0.00051" ixy="-5e-05" ixz="0.0" iyy="0.0005" iyz="0.0" izz="0.00057"/>
    </inertial>
    <visual>
      <origin rpy="0 0 0" xyz="0 0 0"/>
      <geometry>
        <mesh filename="package://robot_description/robot/meshes/leg2_link1.STL"/>
      </geometry>
      <material name="link_1_material"/>
    </visual>
    <collision>
      <origin rpy="1.57 0 0" xyz="0 -0.033 0"/>
      <geometry>
        <cylinder length="0.06" radius="0.038"/>
      </geometry>
    </collision>
  </link>
  <!--joint2-->
  <joint name="leg2_joint2" type="revolute">
    <!--两个坐标系（link）的相对偏移-->
    <origin rpy="0 0 0" xyz="0.0 0.0993 0.0"/>
    <parent link="leg2_link1"/>
    <child link="leg2_link2"/>
    <axis xyz="0 1 0"/>
    <dynamics damping="0.01" friction="0.2"/>
    <limit effort="36.0" lower="-3.14" upper="3.14" velocity="17.3"/>
  </joint>
  <!--link2-->
  <link name="leg2_link2">
    <!--质心偏移-->
    <inertial>
      <origin rpy="0 0 0" xyz="-0.00238 -0.02441 -0.04244"/>
      <mass value="1.22859"/>
      <inertia ixx="0.00754" ixy="-8e-05" ixz="0.00033" iyy="0.00682" iyz="-0.00128" izz="0.00167"/>
    </inertial>
    <visual>
      <origin rpy="0 0 0" xyz="0 0 0"/>
      <geometry>
        <mesh filename="package://robot_description/robot/meshes/leg2_link2.STL"/>
      </geometry>
      <material name="link_2_material"/>
    </visual>
    <!--圆柱和盒子组合-->
    <collision>
      <origin rpy="1.57 0 0" xyz="0 -0.036 0"/>
      <geometry>
        <cylinder length="0.117" radius="0.038"/>
      </geometry>
    </collision>
    <collision>
      <origin rpy="0 1.57 0" xyz="0 0 -0.125"/>
      <geometry>
        <box size="0.165 0.04 0.06"/>
      </geometry>
    </collision>
  </link>
  <!--joint3-->
  <joint name="leg2_joint3" type="revolute">
    <!--两个坐标系（link）的相对偏移-->
    <origin rpy="0 0 0" xyz="0.0 0.0 -0.21"/>
    <parent link="leg2_link2"/>
    <child link="leg2_link3"/>
    <axis xyz="0 1 0"/>
    <dynamics damping="0.01" friction="0.2"/>
    <limit effort="36.0" lower="-3.14" upper="3.14" velocity="17.3"/>
  </joint>
  <!--link3-->
  <link name="leg2_link3">
    <!--质心偏移-->
    <inertial>
      <origin rpy="0 0 0" xyz="0.00418 0.0 -0.09392"/>
      <mass value="0.20045"/>
      <inertia ixx="0.00094" ixy="0.0" ixz="-3e-05" iyy="0.00094" iyz="0.0" izz="3e-05"/>
    </inertial>
    <visual>
      <origin rpy="0 0 0" xyz="0 0 0"/>
      <geometry>
        <mesh filename="package://robot_description/robot/meshes/leg2_link3.STL"/>
      </geometry>
      <material name="link_3_material"/>
    </visual>
    <collision>
      <origin rpy="0 0 0" xyz="0 0 -0.105"/>
      <geometry>
        <cylinder length="0.21" radius="0.019"/>
      </geometry>
    </collision>
  </link>
  <!--joint4-->
  <joint name="leg2_joint4" type="fixed">
    <!--两个坐标系（link）的相对偏移-->
    <origin rpy="0 0 0" xyz="0.0 0.0 -0.21"/>
    <parent link="leg2_link3"/>
    <child link="leg2_link4"/>
    <axis xyz="0 0 0"/>
    <!-- <dynamics damping="0 friction="0"/>
        <limit effort="0" velocity="0" lower="0" upper="0" /> -->
  </joint>
  <!--link4-->
  <link name="leg2_link4">
    <!--质心偏移-->
    <inertial>
      <origin rpy="0 0 0" xyz="-0.00432 0.0 -0.00515"/>
      <mass value="0.01658"/>
      <inertia ixx="1e-05" ixy="0.0" ixz="0.0" iyy="1e-05" iyz="0.0" izz="1e-05"/>
    </inertial>
    <visual>
      <origin rpy="0 0 0" xyz="0 0 0"/>
      <geometry>
        <mesh filename="package://robot_description/robot/meshes/leg2_link4.STL"/>
      </geometry>
      <material name="link_4_material"/>
    </visual>
    <collision>
      <origin rpy="0 0 0" xyz="0 0 0"/>
      <geometry>
        <sphere radius="0.018"/>
      </geometry>
    </collision>
  </link>
  <!-- 指定执行机构 -->
  <!--motor1-->
  <transmission name="leg2_joint1_tran">
    <!--指定传动类型-->
    <type>transmission_interface/SimpleTransmission</type>
    <!--传动系统所连接的关节-->
    <joint name="leg2_joint1">
      <!--硬件接口-->
      <hardwareInterface>hardware_interface/EffortJointInterface</hardwareInterface>
    </joint>
    <!--执行器名称-->
    <actuator name="leg2_joint1_motor">
      <hardwareInterface>hardware_interface/EffortJointInterface</hardwareInterface>
      <!--减速比-->
      <mechanicalReduction>1</mechanicalReduction>
    </actuator>
  </transmission>
  <!--motor2-->
  <transmission name="leg2_joint2_tran">
    <type>transmission_interface/SimpleTransmission</type>
    <joint name="leg2_joint2">
      <hardwareInterface>hardware_interface/EffortJointInterface</hardwareInterface>
    </joint>
    <actuator name="leg2_joint2_motor">
      <hardwareInterface>hardware_interface/EffortJointInterface</hardwareInterface>
      <mechanicalReduction>1</mechanicalReduction>
    </actuator>
  </transmission>
  <!--motor3-->
  <transmission name="leg2_joint3_tran">
    <type>transmission_interface/SimpleTransmission</type>
    <joint name="leg2_joint3">
      <hardwareInterface>hardware_interface/EffortJointInterface</hardwareInterface>
    </joint>
    <actuator name="leg2_joint3_motor">
      <hardwareInterface>hardware_interface/EffortJointInterface</hardwareInterface>
      <mechanicalReduction>1</mechanicalReduction>
    </actuator>
  </transmission>
  <!--joint1-->
  <joint name="leg3_joint1" type="revolute">
    <!--两个坐标系（link）的相对偏移-->
    <origin rpy="-0.0 0 0" xyz="-0.177 -0.0755 0.0"/>
    <parent link="base_link"/>
    <child link="leg3_link1"/>
    <axis xyz="1 0 0"/>
    <dynamics damping="0.01" friction="0.2"/>
    <limit effort="36.0" lower="-3.14" upper="3.14" velocity="17.3"/>
  </joint>
  <!--link1-->
  <link name="leg3_link1">
    <!--质心偏移-->
    <inertial>
      <origin rpy="0 0 0" xyz="0.00461 0.02471 0.00019"/>
      <mass value="0.68678"/>
      <inertia ixx="0.00051" ixy="-5e-05" ixz="-0.0" iyy="0.0005" iyz="-0.0" izz="0.00057"/>
    </inertial>
    <visual>
      <origin rpy="0 0 0" xyz="0 0 0"/>
      <geometry>
        <mesh filename="package://robot_description/robot/meshes/leg3_link1.STL"/>
      </geometry>
      <material name="link_1_material"/>
    </visual>
    <collision>
      <origin rpy="1.57 0 0" xyz="0 0.033 0"/>
      <geometry>
        <cylinder length="0.06" radius="0.038"/>
      </geometry>
    </collision>
  </link>
  <!--joint2-->
  <joint name="leg3_joint2" type="revolute">
    <!--两个坐标系（link）的相对偏移-->
    <origin rpy="0 0 0" xyz="-0.0 -0.0993 0.0"/>
    <parent link="leg3_link1"/>
    <child link="leg3_link2"/>
    <axis xyz="0 1 0"/>
    <dynamics damping="0.01" friction="0.2"/>
    <limit effort="36.0" lower="-3.14" upper="3.14" velocity="17.3"/>
  </joint>
  <!--link2-->
  <link name="leg3_link2">
    <!--质心偏移-->
    <inertial>
      <origin rpy="0 0 0" xyz="0.00238 0.02441 -0.04244"/>
      <mass value="1.22859"/>
      <inertia ixx="0.00754" ixy="-8e-05" ixz="-0.00033" iyy="0.00682" iyz="0.00128" izz="0.00167"/>
    </inertial>
    <visual>
      <origin rpy="0 0 0" xyz="0 0 0"/>
      <geometry>
        <mesh filename="package://robot_description/robot/meshes/leg3_link2.STL"/>
      </geometry>
      <material name="link_2_material"/>
    </visual>
    <!--圆柱和盒子组合-->
    <collision>
      <origin rpy="1.57 0 0" xyz="0 0.036 0"/>
      <geometry>
        <cylinder length="0.117" radius="0.038"/>
      </geometry>
    </collision>
    <collision>
      <origin rpy="0 1.57 0" xyz="0 0 -0.125"/>
      <geometry>
        <box size="0.165 0.04 0.06"/>
      </geometry>
    </collision>
  </link>
  <!--joint3-->
  <joint name="leg3_joint3" type="revolute">
    <!--两个坐标系（link）的相对偏移-->
    <origin rpy="0 0 0" xyz="-0.0 -0.0 -0.21"/>
    <parent link="leg3_link2"/>
    <child link="leg3_link3"/>
    <axis xyz="0 1 0"/>
    <dynamics damping="0.01" friction="0.2"/>
    <limit effort="36.0" lower="-3.14" upper="3.14" velocity="17.3"/>
  </joint>
  <!--link3-->
  <link name="leg3_link3">
    <!--质心偏移-->
    <inertial>
      <origin rpy="0 0 0" xyz="-0.00418 -0.0 -0.09392"/>
      <mass value="0.20045"/>
      <inertia ixx="0.00094" ixy="0.0" ixz="3e-05" iyy="0.00094" iyz="-0.0" izz="3e-05"/>
    </inertial>
    <visual>
      <origin rpy="0 0 0" xyz="0 0 0"/>
      <geometry>
        <mesh filename="package://robot_description/robot/meshes/leg3_link3.STL"/>
      </geometry>
      <material name="link_3_material"/>
    </visual>
    <collision>
      <origin rpy="0 0 0" xyz="0 0 -0.105"/>
      <geometry>
        <cylinder length="0.21" radius="0.019"/>
      </geometry>
    </collision>
  </link>
  <!--joint4-->
  <joint name="leg3_joint4" type="fixed">
    <!--两个坐标系（link）的相对偏移-->
    <origin rpy="0 0 0" xyz="-0.0 -0.0 -0.21"/>
    <parent link="leg3_link3"/>
    <child link="leg3_link4"/>
    <axis xyz="0 0 0"/>
    <!-- <dynamics damping="0 friction="0"/>
        <limit effort="0" velocity="0" lower="0" upper="0" /> -->
  </joint>
  <!--link4-->
  <link name="leg3_link4">
    <!--质心偏移-->
    <inertial>
      <origin rpy="0 0 0" xyz="0.00432 -0.0 -0.00515"/>
      <mass value="0.01658"/>
      <inertia ixx="1e-05" ixy="0.0" ixz="-0.0" iyy="1e-05" iyz="-0.0" izz="1e-05"/>
    </inertial>
    <visual>
      <origin rpy="0 0 0" xyz="0 0 0"/>
      <geometry>
        <mesh filename="package://robot_description/robot/meshes/leg3_link4.STL"/>
      </geometry>
      <material name="link_4_material"/>
    </visual>
    <collision>
      <origin rpy="0 0 0" xyz="0 0 0"/>
      <geometry>
        <sphere radius="0.018"/>
      </geometry>
    </collision>
  </link>
  <!-- 指定执行机构 -->
  <!--motor1-->
  <transmission name="leg3_joint1_tran">
    <!--指定传动类型-->
    <type>transmission_interface/SimpleTransmission</type>
    <!--传动系统所连接的关节-->
    <joint name="leg3_joint1">
      <!--硬件接口-->
      <hardwareInterface>hardware_interface/EffortJointInterface</hardwareInterface>
    </joint>
    <!--执行器名称-->
    <actuator name="leg3_joint1_motor">
      <hardwareInterface>hardware_interface/EffortJointInterface</hardwareInterface>
      <!--减速比-->
      <mechanicalReduction>1</mechanicalReduction>
    </actuator>
  </transmission>
  <!--motor2-->
  <transmission name="leg3_joint2_tran">
    <type>transmission_interface/SimpleTransmission</type>
    <joint name="leg3_joint2">
      <hardwareInterface>hardware_interface/EffortJointInterface</hardwareInterface>
    </joint>
    <actuator name="leg3_joint2_motor">
      <hardwareInterface>hardware_interface/EffortJointInterface</hardwareInterface>
      <mechanicalReduction>1</mechanicalReduction>
    </actuator>
  </transmission>
  <!--motor3-->
  <transmission name="leg3_joint3_tran">
    <type>transmission_interface/SimpleTransmission</type>
    <joint name="leg3_joint3">
      <hardwareInterface>hardware_interface/EffortJointInterface</hardwareInterface>
    </joint>
    <actuator name="leg3_joint3_motor">
      <hardwareInterface>hardware_interface/EffortJointInterface</hardwareInterface>
      <mechanicalReduction>1</mechanicalReduction>
    </actuator>
  </transmission>
  <!--joint1-->
  <joint name="leg4_joint1" type="revolute">
    <!--两个坐标系（link）的相对偏移-->
    <origin rpy="0.0 0 0" xyz="-0.177 0.0755 0.0"/>
    <parent link="base_link"/>
    <child link="leg4_link1"/>
    <axis xyz="1 0 0"/>
    <dynamics damping="0.01" friction="0.2"/>
    <limit effort="36.0" lower="-3.14" upper="3.14" velocity="17.3"/>
  </joint>
  <!--link1-->
  <link name="leg4_link1">
    <!--质心偏移-->
    <inertial>
      <origin rpy="0 0 0" xyz="0.00461 -0.02471 0.00019"/>
      <mass value="0.68678"/>
      <inertia ixx="0.00051" ixy="5e-05" ixz="-0.0" iyy="0.0005" iyz="0.0" izz="0.00057"/>
    </inertial>
    <visual>
      <origin rpy="0 0 0" xyz="0 0 0"/>
      <geometry>
        <mesh filename="package://robot_description/robot/meshes/leg4_link1.STL"/>
      </geometry>
      <material name="link_1_material"/>
    </visual>
    <collision>
      <origin rpy="1.57 0 0" xyz="0 -0.033 0"/>
      <geometry>
        <cylinder length="0.06" radius="0.038"/>
      </geometry>
    </collision>
  </link>
  <!--joint2-->
  <joint name="leg4_joint2" type="revolute">
    <!--两个坐标系（link）的相对偏移-->
    <origin rpy="0 0 0" xyz="-0.0 0.0993 0.0"/>
    <parent link="leg4_link1"/>
    <child link="leg4_link2"/>
    <axis xyz="0 1 0"/>
    <dynamics damping="0.01" friction="0.2"/>
    <limit effort="36.0" lower="-3.14" upper="3.14" velocity="17.3"/>
  </joint>
  <!--link2-->
  <link name="leg4_link2">
    <!--质心偏移-->
    <inertial>
      <origin rpy="0 0 0" xyz="0.00238 -0.02441 -0.04244"/>
      <mass value="1.22859"/>
      <inertia ixx="0.00754" ixy="8e-05" ixz="-0.00033" iyy="0.00682" iyz="-0.00128" izz="0.00167"/>
    </inertial>
    <visual>
      <origin rpy="0 0 0" xyz="0 0 0"/>
      <geometry>
        <mesh filename="package://robot_description/robot/meshes/leg4_link2.STL"/>
      </geometry>
      <material name="link_2_material"/>
    </visual>
    <!--圆柱和盒子组合-->
    <collision>
      <origin rpy="1.57 0 0" xyz="0 -0.036 0"/>
      <geometry>
        <cylinder length="0.117" radius="0.038"/>
      </geometry>
    </collision>
    <collision>
      <origin rpy="0 1.57 0" xyz="0 0 -0.125"/>
      <geometry>
        <box size="0.165 0.04 0.06"/>
      </geometry>
    </collision>
  </link>
  <!--joint3-->
  <joint name="leg4_joint3" type="revolute">
    <!--两个坐标系（link）的相对偏移-->
    <origin rpy="0 0 0" xyz="-0.0 0.0 -0.21"/>
    <parent link="leg4_link2"/>
    <child link="leg4_link3"/>
    <axis xyz="0 1 0"/>
    <dynamics damping="0.01" friction="0.2"/>
    <limit effort="36.0" lower="-3.14" upper="3.14" velocity="17.3"/>
  </joint>
  <!--link3-->
  <link name="leg4_link3">
    <!--质心偏移-->
    <inertial>
      <origin rpy="0 0 0" xyz="-0.00418 0.0 -0.09392"/>
      <mass value="0.20045"/>
      <inertia ixx="0.00094" ixy="-0.0" ixz="3e-05" iyy="0.00094" iyz="0.0" izz="3e-05"/>
    </inertial>
    <visual>
      <origin rpy="0 0 0" xyz="0 0 0"/>
      <geometry>
        <mesh filename="package://robot_description/robot/meshes/leg4_link3.STL"/>
      </geometry>
      <material name="link_3_material"/>
    </visual>
    <collision>
      <origin rpy="0 0 0" xyz="0 0 -0.105"/>
      <geometry>
        <cylinder length="0.21" radius="0.019"/>
      </geometry>
    </collision>
  </link>
  <!--joint4-->
  <joint name="leg4_joint4" type="fixed">
    <!--两个坐标系（link）的相对偏移-->
    <origin rpy="0 0 0" xyz="-0.0 0.0 -0.21"/>
    <parent link="leg4_link3"/>
    <child link="leg4_link4"/>
    <axis xyz="0 0 0"/>
    <!-- <dynamics damping="0 friction="0"/>
        <limit effort="0" velocity="0" lower="0" upper="0" /> -->
  </joint>
  <!--link4-->
  <link name="leg4_link4">
    <!--质心偏移-->
    <inertial>
      <origin rpy="0 0 0" xyz="0.00432 0.0 -0.00515"/>
      <mass value="0.01658"/>
      <inertia ixx="1e-05" ixy="-0.0" ixz="-0.0" iyy="1e-05" iyz="0.0" izz="1e-05"/>
    </inertial>
    <visual>
      <origin rpy="0 0 0" xyz="0 0 0"/>
      <geometry>
        <mesh filename="package://robot_description/robot/meshes/leg4_link4.STL"/>
      </geometry>
      <material name="link_4_material"/>
    </visual>
    <collision>
      <origin rpy="0 0 0" xyz="0 0 0"/>
      <geometry>
        <sphere radius="0.018"/>
      </geometry>
    </collision>
  </link>
  <!-- 指定执行机构 -->
  <!--motor1-->
  <transmission name="leg4_joint1_tran">
    <!--指定传动类型-->
    <type>transmission_interface/SimpleTransmission</type>
    <!--传动系统所连接的关节-->
    <joint name="leg4_joint1">
      <!--硬件接口-->
      <hardwareInterface>hardware_interface/EffortJointInterface</hardwareInterface>
    </joint>
    <!--执行器名称-->
    <actuator name="leg4_joint1_motor">
      <hardwareInterface>hardware_interface/EffortJointInterface</hardwareInterface>
      <!--减速比-->
      <mechanicalReduction>1</mechanicalReduction>
    </actuator>
  </transmission>
  <!--motor2-->
  <transmission name="leg4_joint2_tran">
    <type>transmission_interface/SimpleTransmission</type>
    <joint name="leg4_joint2">
      <hardwareInterface>hardware_interface/EffortJointInterface</hardwareInterface>
    </joint>
    <actuator name="leg4_joint2_motor">
      <hardwareInterface>hardware_interface/EffortJointInterface</hardwareInterface>
      <mechanicalReduction>1</mechanicalReduction>
    </actuator>
  </transmission>
  <!--motor3-->
  <transmission name="leg4_joint3_tran">
    <type>transmission_interface/SimpleTransmission</type>
    <joint name="leg4_joint3">
      <hardwareInterface>hardware_interface/EffortJointInterface</hardwareInterface>
    </joint>
    <actuator name="leg4_joint3_motor">
      <hardwareInterface>hardware_interface/EffortJointInterface</hardwareInterface>
      <mechanicalReduction>1</mechanicalReduction>
    </actuator>
  </transmission>
  <!--imu-->
  <!-- Imu joint -->
  <joint name="imu_joint" type="fixed">
    <origin rpy="0 0 0" xyz="0 0 0"/>
    <parent link="base_link"/>
    <child link="imu_link"/>
  </joint>
  <!-- Imu link -->
  <link name="imu_link">
    <!-- 材料 -->
    <inertial>
      <mass value="0.01"/>
      <origin rpy="0 0 0" xyz="0 0 0"/>
      <inertia ixx="0.000001" ixy="0" ixz="0" iyy="0.000001" iyz="0" izz="0.000001"/>
    </inertial>
    <!-- 可视化 -->
    <visual>
      <origin rpy="0 0 0" xyz="0 0 0"/>
      <geometry>
        <box size="0.015 0.015 0.004"/>
      </geometry>
    </visual>
    <!-- 颜色 -->
    <material name="orange">
      <color rgba="255 108 10 255"/>
    </material>
  </link>
</robot>

